INFO     my_log:test_auth.py:83 Auth - 4：错误的Akey ---> Pass